Workbook

Sheet How it works
A1: Asset Allocation - month by month
A3: THE IDEA
A4: You put your capital into Nifty, Gold, Bonds and Cash ONCE, at the month-end close of December 1995, and never sell. Every month each part grows with its own price or rate. The sheet runs month by month from 1996-01 to the last complete month.
A6: STEPS
A7: 1. Nifty x = Nifty month-end close / the December 1995 close. Gold x works the same with the gold price in Rs per gram (India rate, incl. 3% GST).
A8: 2. Gold before 2005-06 comes from the 'Gold 1995-2005' sheet: the GOLDINR month-end close x a matching factor (MCX / GOLDINR on 2005-06-30); from 2005-06 the MCX month-end close / 10. Both x 1.03 GST (cell Data!P1), a constant, so it changes no return. The API's MCX price is frozen from 2020-03-20 to 2020-06-02, so the Mar / Apr / May 2020 month-ends are estimates (see the Note column in 'Data').
A9: 3. Bonds: one return per year, Jan to Dec (sheet 'Bonds calculation'), added once in December; the other months are 0%. Until 2011 the return is the SBI year-end FD rate (9.00% applied to 1996-98); 2012-2014 use the 2011 rate (9.25%); from 2015 it is the move of the NIFTY Composite G-sec Index (December / last December - 1). 2026 runs from the 2025 December close to the last complete month and is added in that month. Bonds x = previous Bonds x x (1 + the month's return).
A10: 4. Cash x is always 1 (hand cash earns nothing).
A11: 5. Each part's value = money put in x its x. Portfolio = Nifty part + Gold part + Bonds part + Cash part (sheet 'Monthly').
A12: 6. Inflation: the year's annual CPI rate (TradeEntry API; 2026 repeats the 2025 rate because the API has no 2026 value yet) as an equal monthly rate. Inflation x = previous x x (1 + annual/100)^(1/12). Value after inflation = Portfolio / Inflation x.
A13: 7. Drawdown = Portfolio / highest earlier Portfolio - 1. 'Year by year' shows the December value of each year (2026: the last month).
A14: 8. Rebalance year by year sheet: every December each part's share of the portfolio is compared with its target %; if any is more than the tolerance (B2, default 5 points; 0 = every year) away, ALL parts are reset to the target % (sell what grew too much, buy what fell behind); otherwise nothing is traded. Nifty shares and gold grams change only in those Decembers.
... A27: Colors: blue text = data, black = formula, yellow cell = you change it. Rupee values have no decimals, other numbers 2 decimals.

Sheet Calculator
A1: Calculator - month by month
A3: INPUTS
A4: Total capital (Rs) | B4: 200000
A5: Nifty % | B5: 50
A6: Gold % | B6: 30
A7: Bonds % | B7: 15
A8: Cash % (auto = 100 minus the others) | B8: =100-B5-B6-B7 | C8: =IF(B8<0,"Weights add up to more than 100% - lower Nifty / Gold / Bonds","")
A9: Show values at month (YYYY-MM) | B9: 2026-09
A10: Row of that month in Monthly | B10: =MATCH(B9,Monthly!$A$1:$A$500,0)
A11: Months held | B11: =B10-5
A12: Years held | B12: =B11/12
A14: RESULTS
A15: Portfolio value Rs | B15: =INDEX(Monthly!$K$1:$K$500,$B$10)
A16: Value after inflation Rs | B16: =INDEX(Monthly!$L$1:$L$500,$B$10)
A17: Nifty part Rs | B17: =INDEX(Monthly!$G$1:$G$500,$B$10)
A18: Gold part Rs | B18: =INDEX(Monthly!$H$1:$H$500,$B$10)
A19: Bonds part Rs | B19: =INDEX(Monthly!$I$1:$I$500,$B$10)
A20: Cash part Rs | B20: =INDEX(Monthly!$J$1:$J$500,$B$10)
A21: Worst fall so far (drawdown) | B21: =INDEX(Monthly!$N$1:$N$500,$B$10)
A22: 100% in Nifty Rs | B22: =INDEX(Monthly!$O$1:$O$500,$B$10)
A23: 100% in Gold Rs | B23: =INDEX(Monthly!$P$1:$P$500,$B$10)
A24: 100% in Bonds Rs | B24: =INDEX(Monthly!$Q$1:$Q$500,$B$10)
A25: Inflation: Rs needed to keep up | B25: =INDEX(Monthly!$R$1:$R$500,$B$10)
A26: Growth per year | B26: =IF($B$11>0,(B15/$B$4)^(12/$B$11)-1,0)
A29: WHAT YOU BOUGHT AT THE START (Dec 1995 close)
B30: Money put in Rs | C30: Price at the start | D30: Shares / grams bought | E30: Worth at the month shown Rs
A31: Nifty (shares) | B31: =$B$4*$B$5/100 | C31: =Data!C5 | D31: =B31/C31 | E31: =D31*INDEX(Data!$C$1:$C$500,$B$10)
A32: Gold (grams, India rate) | B32: =$B$4*$B$6/100 | C32: =Data!G5 | D32: =B32/C32 | E32: =D32*INDEX(Data!$G$1:$G$500,$B$10)
A33: Bonds (money, grows with Bonds x) | B33: =$B$4*$B$7/100 | E33: =INDEX(Monthly!$I$1:$I$500,$B$10)
A34: Cash (stays the same) | B34: =$B$4*$B$8/100 | E34: =INDEX(Monthly!$J$1:$J$500,$B$10)
A35: Total | B35: =SUM(B31:B34) | E35: =SUM(E31:E34)

Sheet Monthly
A1: Monthly - every number is a formula
A4: Period | B4: Nifty x | C4: Gold x | D4: Bonds x | E4: Cash x | F4: Inflation x | G4: Nifty Rs | H4: Gold Rs | I4: Bonds Rs | J4: Cash Rs | K4: Portfolio Rs | L4: After inflation Rs | M4: Peak Rs | N4: Drawdown | O4: 100% Nifty Rs | P4: 100% Gold Rs | Q4: 100% Bonds Rs | R4: Inflation Rs
A5: =Data!A5 | B5: 1 | C5: 1 | D5: 1 | E5: 1 | F5: 1 | G5: =Calculator!$B$4*Calculator!$B$5/100*B5 | H5: =Calculator!$B$4*Calculator!$B$6/100*C5 | I5: =Calculator!$B$4*Calculator!$B$7/100*D5 | J5: =Calculator!$B$4*Calculator!$B$8/100*E5 | K5: =SUM(G5:J5) | L5: =K5/F5 | M5: =Calculator!$B$4 | N5: =K5/M5-1 | O5: =Calculator!$B$4*B5 | P5: =Calculator!$B$4*C5 | Q5: =Calculator!$B$4*D5 | R5: =Calculator!$B$4*F5
A6: =Data!A6 | B6: =Data!C6/Data!$C$5 | C6: =Data!G6/Data!$G$5 | D6: =D5*(1+Data!I6/100) | E6: 1 | F6: =F5*(1+Data!H6/100)^(1/12) | G6: =Calculator!$B$4*Calculator!$B$5/100*B6 | H6: =Calculator!$B$4*Calculator!$B$6/100*C6 | I6: =Calculator!$B$4*Calculator!$B$7/100*D6 | J6: =Calculator!$B$4*Calculator!$B$8/100*E6 | K6: =SUM(G6:J6) | L6: =K6/F6 | M6: =MAX(M5,K6) | N6: =K6/M6-1 | O6: =Calculator!$B$4*B6 | P6: =Calculator!$B$4*C6 | Q6: =Calculator!$B$4*D6 | R6: =Calculator!$B$4*F6
A7: =Data!A7 | B7: =Data!C7/Data!$C$5 | C7: =Data!G7/Data!$G$5 | D7: =D6*(1+Data!I7/100) | E7: 1 | F7: =F6*(1+Data!H7/100)^(1/12) | G7: =Calculator!$B$4*Calculator!$B$5/100*B7 | H7: =Calculator!$B$4*Calculator!$B$6/100*C7 | I7: =Calculator!$B$4*Calculator!$B$7/100*D7 | J7: =Calculator!$B$4*Calculator!$B$8/100*E7 | K7: =SUM(G7:J7) | L7: =K7/F7 | M7: =MAX(M6,K7) | N7: =K7/M7-1 | O7: =Calculator!$B$4*B7 | P7: =Calculator!$B$4*C7 | Q7: =Calculator!$B$4*D7 | R7: =Calculator!$B$4*F7
A8: =Data!A8 | B8: =Data!C8/Data!$C$5 | C8: =Data!G8/Data!$G$5 | D8: =D7*(1+Data!I8/100) | E8: 1 | F8: =F7*(1+Data!H8/100)^(1/12) | G8: =Calculator!$B$4*Calculator!$B$5/100*B8 | H8: =Calculator!$B$4*Calculator!$B$6/100*C8 | I8: =Calculator!$B$4*Calculator!$B$7/100*D8 | J8: =Calculator!$B$4*Calculator!$B$8/100*E8 | K8: =SUM(G8:J8) | L8: =K8/F8 | M8: =MAX(M7,K8) | N8: =K8/M8-1 | O8: =Calculator!$B$4*B8 | P8: =Calculator!$B$4*C8 | Q8: =Calculator!$B$4*D8 | R8: =Calculator!$B$4*F8
A9: =Data!A9 | B9: =Data!C9/Data!$C$5 | C9: =Data!G9/Data!$G$5 | D9: =D8*(1+Data!I9/100) | E9: 1 | F9: =F8*(1+Data!H9/100)^(1/12) | G9: =Calculator!$B$4*Calculator!$B$5/100*B9 | H9: =Calculator!$B$4*Calculator!$B$6/100*C9 | I9: =Calculator!$B$4*Calculator!$B$7/100*D9 | J9: =Calculator!$B$4*Calculator!$B$8/100*E9 | K9: =SUM(G9:J9) | L9: =K9/F9 | M9: =MAX(M8,K9) | N9: =K9/M9-1 | O9: =Calculator!$B$4*B9 | P9: =Calculator!$B$4*C9 | Q9: =Calculator!$B$4*D9 | R9: =Calculator!$B$4*F9
A10: =Data!A10 | B10: =Data!C10/Data!$C$5 | C10: =Data!G10/Data!$G$5 | D10: =D9*(1+Data!I10/100) | E10: 1 | F10: =F9*(1+Data!H10/100)^(1/12) | G10: =Calculator!$B$4*Calculator!$B$5/100*B10 | H10: =Calculator!$B$4*Calculator!$B$6/100*C10 | I10: =Calculator!$B$4*Calculator!$B$7/100*D10 | J10: =Calculator!$B$4*Calculator!$B$8/100*E10 | K10: =SUM(G10:J10) | L10: =K10/F10 | M10: =MAX(M9,K10) | N10: =K10/M10-1 | O10: =Calculator!$B$4*B10 | P10: =Calculator!$B$4*C10 | Q10: =Calculator!$B$4*D10 | R10: =Calculator!$B$4*F10
A11: =Data!A11 | B11: =Data!C11/Data!$C$5 | C11: =Data!G11/Data!$G$5 | D11: =D10*(1+Data!I11/100) | E11: 1 | F11: =F10*(1+Data!H11/100)^(1/12) | G11: =Calculator!$B$4*Calculator!$B$5/100*B11 | H11: =Calculator!$B$4*Calculator!$B$6/100*C11 | I11: =Calculator!$B$4*Calculator!$B$7/100*D11 | J11: =Calculator!$B$4*Calculator!$B$8/100*E11 | K11: =SUM(G11:J11) | L11: =K11/F11 | M11: =MAX(M10,K11) | N11: =K11/M11-1 | O11: =Calculator!$B$4*B11 | P11: =Calculator!$B$4*C11 | Q11: =Calculator!$B$4*D11 | R11: =Calculator!$B$4*F11
A12: =Data!A12 | B12: =Data!C12/Data!$C$5 | C12: =Data!G12/Data!$G$5 | D12: =D11*(1+Data!I12/100) | E12: 1 | F12: =F11*(1+Data!H12/100)^(1/12) | G12: =Calculator!$B$4*Calculator!$B$5/100*B12 | H12: =Calculator!$B$4*Calculator!$B$6/100*C12 | I12: =Calculator!$B$4*Calculator!$B$7/100*D12 | J12: =Calculator!$B$4*Calculator!$B$8/100*E12 | K12: =SUM(G12:J12) | L12: =K12/F12 | M12: =MAX(M11,K12) | N12: =K12/M12-1 | O12: =Calculator!$B$4*B12 | P12: =Calculator!$B$4*C12 | Q12: =Calculator!$B$4*D12 | R12: =Calculator!$B$4*F12
A13: =Data!A13 | B13: =Data!C13/Data!$C$5 | C13: =Data!G13/Data!$G$5 | D13: =D12*(1+Data!I13/100) | E13: 1 | F13: =F12*(1+Data!H13/100)^(1/12) | G13: =Calculator!$B$4*Calculator!$B$5/100*B13 | H13: =Calculator!$B$4*Calculator!$B$6/100*C13 | I13: =Calculator!$B$4*Calculator!$B$7/100*D13 | J13: =Calculator!$B$4*Calculator!$B$8/100*E13 | K13: =SUM(G13:J13) | L13: =K13/F13 | M13: =MAX(M12,K13) | N13: =K13/M13-1 | O13: =Calculator!$B$4*B13 | P13: =Calculator!$B$4*C13 | Q13: =Calculator!$B$4*D13 | R13: =Calculator!$B$4*F13
A14: =Data!A14 | B14: =Data!C14/Data!$C$5 | C14: =Data!G14/Data!$G$5 | D14: =D13*(1+Data!I14/100) | E14: 1 | F14: =F13*(1+Data!H14/100)^(1/12) | G14: =Calculator!$B$4*Calculator!$B$5/100*B14 | H14: =Calculator!$B$4*Calculator!$B$6/100*C14 | I14: =Calculator!$B$4*Calculator!$B$7/100*D14 | J14: =Calculator!$B$4*Calculator!$B$8/100*E14 | K14: =SUM(G14:J14) | L14: =K14/F14 | M14: =MAX(M13,K14) | N14: =K14/M14-1 | O14: =Calculator!$B$4*B14 | P14: =Calculator!$B$4*C14 | Q14: =Calculator!$B$4*D14 | R14: =Calculator!$B$4*F14
A15: =Data!A15 | B15: =Data!C15/Data!$C$5 | C15: =Data!G15/Data!$G$5 | D15: =D14*(1+Data!I15/100) | E15: 1 | F15: =F14*(1+Data!H15/100)^(1/12) | G15: =Calculator!$B$4*Calculator!$B$5/100*B15 | H15: =Calculator!$B$4*Calculator!$B$6/100*C15 | I15: =Calculator!$B$4*Calculator!$B$7/100*D15 | J15: =Calculator!$B$4*Calculator!$B$8/100*E15 | K15: =SUM(G15:J15) | L15: =K15/F15 | M15: =MAX(M14,K15) | N15: =K15/M15-1 | O15: =Calculator!$B$4*B15 | P15: =Calculator!$B$4*C15 | Q15: =Calculator!$B$4*D15 | R15: =Calculator!$B$4*F15
A16: =Data!A16 | B16: =Data!C16/Data!$C$5 | C16: =Data!G16/Data!$G$5 | D16: =D15*(1+Data!I16/100) | E16: 1 | F16: =F15*(1+Data!H16/100)^(1/12) | G16: =Calculator!$B$4*Calculator!$B$5/100*B16 | H16: =Calculator!$B$4*Calculator!$B$6/100*C16 | I16: =Calculator!$B$4*Calculator!$B$7/100*D16 | J16: =Calculator!$B$4*Calculator!$B$8/100*E16 | K16: =SUM(G16:J16) | L16: =K16/F16 | M16: =MAX(M15,K16) | N16: =K16/M16-1 | O16: =Calculator!$B$4*B16 | P16: =Calculator!$B$4*C16 | Q16: =Calculator!$B$4*D16 | R16: =Calculator!$B$4*F16
A17: =Data!A17 | B17: =Data!C17/Data!$C$5 | C17: =Data!G17/Data!$G$5 | D17: =D16*(1+Data!I17/100) | E17: 1 | F17: =F16*(1+Data!H17/100)^(1/12) | G17: =Calculator!$B$4*Calculator!$B$5/100*B17 | H17: =Calculator!$B$4*Calculator!$B$6/100*C17 | I17: =Calculator!$B$4*Calculator!$B$7/100*D17 | J17: =Calculator!$B$4*Calculator!$B$8/100*E17 | K17: =SUM(G17:J17) | L17: =K17/F17 | M17: =MAX(M16,K17) | N17: =K17/M17-1 | O17: =Calculator!$B$4*B17 | P17: =Calculator!$B$4*C17 | Q17: =Calculator!$B$4*D17 | R17: =Calculator!$B$4*F17
... A374: =Data!A374 | B374: =Data!C374/Data!$C$5 | C374: =Data!G374/Data!$G$5 | D374: =D373*(1+Data!I374/100) | E374: 1 | F374: =F373*(1+Data!H374/100)^(1/12) | G374: =Calculator!$B$4*Calculator!$B$5/100*B374 | H374: =Calculator!$B$4*Calculator!$B$6/100*C374 | I374: =Calculator!$B$4*Calculator!$B$7/100*D374 | J374: =Calculator!$B$4*Calculator!$B$8/100*E374 | K374: =SUM(G374:J374) | L374: =K374/F374 | M374: =MAX(M373,K374) | N374: =K374/M374-1 | O374: =Calculator!$B$4*B374 | P374: =Calculator!$B$4*C374 | Q374: =Calculator!$B$4*D374 | R374: =Calculator!$B$4*F374

Sheet Year by year
A1: Year by year (first row = what you bought at the Dec 1995 close; then the December value of each year, the last year ends at the last complete month)
A4: Year | B4: Months in year | C4: Row of year-end month in Monthly | D4: Nifty Rs | E4: Gold Rs | F4: Bonds Rs | G4: Cash Rs | H4: Portfolio Rs | I4: Return that year | J4: Inflation % | K4: After inflation Rs | L4: Avg per year so far
A5: 1995 | B5: 0 | C5: =4+COUNTIF(Data!$B$5:$B$500,"<="&A5) | D5: =INDEX(Monthly!$G$1:$G$500,$C5) | E5: =INDEX(Monthly!$H$1:$H$500,$C5) | F5: =INDEX(Monthly!$I$1:$I$500,$C5) | G5: =INDEX(Monthly!$J$1:$J$500,$C5) | H5: =INDEX(Monthly!$K$1:$K$500,$C5) | K5: =INDEX(Monthly!$L$1:$L$500,$C5)
A6: 1996 | B6: =C6-C5 | C6: =4+COUNTIF(Data!$B$5:$B$500,"<="&A6) | D6: =INDEX(Monthly!$G$1:$G$500,$C6) | E6: =INDEX(Monthly!$H$1:$H$500,$C6) | F6: =INDEX(Monthly!$I$1:$I$500,$C6) | G6: =INDEX(Monthly!$J$1:$J$500,$C6) | H6: =INDEX(Monthly!$K$1:$K$500,$C6) | I6: =H6/H5-1 | J6: =INDEX(Data!$H$1:$H$500,$C6) | K6: =INDEX(Monthly!$L$1:$L$500,$C6) | L6: =(H6/Calculator!$B$4)^(12/(C6-$C$5))-1
A7: 1997 | B7: =C7-C6 | C7: =4+COUNTIF(Data!$B$5:$B$500,"<="&A7) | D7: =INDEX(Monthly!$G$1:$G$500,$C7) | E7: =INDEX(Monthly!$H$1:$H$500,$C7) | F7: =INDEX(Monthly!$I$1:$I$500,$C7) | G7: =INDEX(Monthly!$J$1:$J$500,$C7) | H7: =INDEX(Monthly!$K$1:$K$500,$C7) | I7: =H7/H6-1 | J7: =INDEX(Data!$H$1:$H$500,$C7) | K7: =INDEX(Monthly!$L$1:$L$500,$C7) | L7: =(H7/Calculator!$B$4)^(12/(C7-$C$5))-1
A8: 1998 | B8: =C8-C7 | C8: =4+COUNTIF(Data!$B$5:$B$500,"<="&A8) | D8: =INDEX(Monthly!$G$1:$G$500,$C8) | E8: =INDEX(Monthly!$H$1:$H$500,$C8) | F8: =INDEX(Monthly!$I$1:$I$500,$C8) | G8: =INDEX(Monthly!$J$1:$J$500,$C8) | H8: =INDEX(Monthly!$K$1:$K$500,$C8) | I8: =H8/H7-1 | J8: =INDEX(Data!$H$1:$H$500,$C8) | K8: =INDEX(Monthly!$L$1:$L$500,$C8) | L8: =(H8/Calculator!$B$4)^(12/(C8-$C$5))-1
A9: 1999 | B9: =C9-C8 | C9: =4+COUNTIF(Data!$B$5:$B$500,"<="&A9) | D9: =INDEX(Monthly!$G$1:$G$500,$C9) | E9: =INDEX(Monthly!$H$1:$H$500,$C9) | F9: =INDEX(Monthly!$I$1:$I$500,$C9) | G9: =INDEX(Monthly!$J$1:$J$500,$C9) | H9: =INDEX(Monthly!$K$1:$K$500,$C9) | I9: =H9/H8-1 | J9: =INDEX(Data!$H$1:$H$500,$C9) | K9: =INDEX(Monthly!$L$1:$L$500,$C9) | L9: =(H9/Calculator!$B$4)^(12/(C9-$C$5))-1
A10: 2000 | B10: =C10-C9 | C10: =4+COUNTIF(Data!$B$5:$B$500,"<="&A10) | D10: =INDEX(Monthly!$G$1:$G$500,$C10) | E10: =INDEX(Monthly!$H$1:$H$500,$C10) | F10: =INDEX(Monthly!$I$1:$I$500,$C10) | G10: =INDEX(Monthly!$J$1:$J$500,$C10) | H10: =INDEX(Monthly!$K$1:$K$500,$C10) | I10: =H10/H9-1 | J10: =INDEX(Data!$H$1:$H$500,$C10) | K10: =INDEX(Monthly!$L$1:$L$500,$C10) | L10: =(H10/Calculator!$B$4)^(12/(C10-$C$5))-1
A11: 2001 | B11: =C11-C10 | C11: =4+COUNTIF(Data!$B$5:$B$500,"<="&A11) | D11: =INDEX(Monthly!$G$1:$G$500,$C11) | E11: =INDEX(Monthly!$H$1:$H$500,$C11) | F11: =INDEX(Monthly!$I$1:$I$500,$C11) | G11: =INDEX(Monthly!$J$1:$J$500,$C11) | H11: =INDEX(Monthly!$K$1:$K$500,$C11) | I11: =H11/H10-1 | J11: =INDEX(Data!$H$1:$H$500,$C11) | K11: =INDEX(Monthly!$L$1:$L$500,$C11) | L11: =(H11/Calculator!$B$4)^(12/(C11-$C$5))-1
A12: 2002 | B12: =C12-C11 | C12: =4+COUNTIF(Data!$B$5:$B$500,"<="&A12) | D12: =INDEX(Monthly!$G$1:$G$500,$C12) | E12: =INDEX(Monthly!$H$1:$H$500,$C12) | F12: =INDEX(Monthly!$I$1:$I$500,$C12) | G12: =INDEX(Monthly!$J$1:$J$500,$C12) | H12: =INDEX(Monthly!$K$1:$K$500,$C12) | I12: =H12/H11-1 | J12: =INDEX(Data!$H$1:$H$500,$C12) | K12: =INDEX(Monthly!$L$1:$L$500,$C12) | L12: =(H12/Calculator!$B$4)^(12/(C12-$C$5))-1
A13: 2003 | B13: =C13-C12 | C13: =4+COUNTIF(Data!$B$5:$B$500,"<="&A13) | D13: =INDEX(Monthly!$G$1:$G$500,$C13) | E13: =INDEX(Monthly!$H$1:$H$500,$C13) | F13: =INDEX(Monthly!$I$1:$I$500,$C13) | G13: =INDEX(Monthly!$J$1:$J$500,$C13) | H13: =INDEX(Monthly!$K$1:$K$500,$C13) | I13: =H13/H12-1 | J13: =INDEX(Data!$H$1:$H$500,$C13) | K13: =INDEX(Monthly!$L$1:$L$500,$C13) | L13: =(H13/Calculator!$B$4)^(12/(C13-$C$5))-1
A14: 2004 | B14: =C14-C13 | C14: =4+COUNTIF(Data!$B$5:$B$500,"<="&A14) | D14: =INDEX(Monthly!$G$1:$G$500,$C14) | E14: =INDEX(Monthly!$H$1:$H$500,$C14) | F14: =INDEX(Monthly!$I$1:$I$500,$C14) | G14: =INDEX(Monthly!$J$1:$J$500,$C14) | H14: =INDEX(Monthly!$K$1:$K$500,$C14) | I14: =H14/H13-1 | J14: =INDEX(Data!$H$1:$H$500,$C14) | K14: =INDEX(Monthly!$L$1:$L$500,$C14) | L14: =(H14/Calculator!$B$4)^(12/(C14-$C$5))-1
A15: 2005 | B15: =C15-C14 | C15: =4+COUNTIF(Data!$B$5:$B$500,"<="&A15) | D15: =INDEX(Monthly!$G$1:$G$500,$C15) | E15: =INDEX(Monthly!$H$1:$H$500,$C15) | F15: =INDEX(Monthly!$I$1:$I$500,$C15) | G15: =INDEX(Monthly!$J$1:$J$500,$C15) | H15: =INDEX(Monthly!$K$1:$K$500,$C15) | I15: =H15/H14-1 | J15: =INDEX(Data!$H$1:$H$500,$C15) | K15: =INDEX(Monthly!$L$1:$L$500,$C15) | L15: =(H15/Calculator!$B$4)^(12/(C15-$C$5))-1
A16: 2006 | B16: =C16-C15 | C16: =4+COUNTIF(Data!$B$5:$B$500,"<="&A16) | D16: =INDEX(Monthly!$G$1:$G$500,$C16) | E16: =INDEX(Monthly!$H$1:$H$500,$C16) | F16: =INDEX(Monthly!$I$1:$I$500,$C16) | G16: =INDEX(Monthly!$J$1:$J$500,$C16) | H16: =INDEX(Monthly!$K$1:$K$500,$C16) | I16: =H16/H15-1 | J16: =INDEX(Data!$H$1:$H$500,$C16) | K16: =INDEX(Monthly!$L$1:$L$500,$C16) | L16: =(H16/Calculator!$B$4)^(12/(C16-$C$5))-1
A17: 2007 | B17: =C17-C16 | C17: =4+COUNTIF(Data!$B$5:$B$500,"<="&A17) | D17: =INDEX(Monthly!$G$1:$G$500,$C17) | E17: =INDEX(Monthly!$H$1:$H$500,$C17) | F17: =INDEX(Monthly!$I$1:$I$500,$C17) | G17: =INDEX(Monthly!$J$1:$J$500,$C17) | H17: =INDEX(Monthly!$K$1:$K$500,$C17) | I17: =H17/H16-1 | J17: =INDEX(Data!$H$1:$H$500,$C17) | K17: =INDEX(Monthly!$L$1:$L$500,$C17) | L17: =(H17/Calculator!$B$4)^(12/(C17-$C$5))-1
... A36: 2026 | B36: =C36-C35 | C36: =4+COUNTIF(Data!$B$5:$B$500,"<="&A36) | D36: =INDEX(Monthly!$G$1:$G$500,$C36) | E36: =INDEX(Monthly!$H$1:$H$500,$C36) | F36: =INDEX(Monthly!$I$1:$I$500,$C36) | G36: =INDEX(Monthly!$J$1:$J$500,$C36) | H36: =INDEX(Monthly!$K$1:$K$500,$C36) | I36: =H36/H35-1 | J36: =INDEX(Data!$H$1:$H$500,$C36) | K36: =INDEX(Monthly!$L$1:$L$500,$C36) | L36: =(H36/Calculator!$B$4)^(12/(C36-$C$5))-1

Sheet Asset tracker
A1: Asset tracker: what you hold in each asset, year by year (December values; the last year ends at the last complete month)
A2: Share = the Nifty shares / gold grams you bought once at the start (Dec 1995 close) (never sold). Value = Share x price. Target Value = target % x the whole portfolio that year. Buy/Sell = Target Value - Value (+ buy, - sell) to get back to your target. Annual Return = price change in the year. Peak = highest Value so far, Drawdown % = Value / Peak - 1, CAGR % = yearly growth since the start.
A4: Year | B4: Row in Data | C4: Nifty price | D4: Shares | E4: Nifty Value | F4: Nifty Target Value | G4: Buy/Sell | H4: Annual Return | I4: Peak | J4: Drawdown % | K4: CAGR % | L4: Gold ₹/g | M4: Gold (g) | N4: Gold Value | O4: Target Value | P4: Buy/Sell | Q4: Annual Return | R4: Peak | S4: Drawdown % | T4: CAGR % | U4: Bonds x | V4: Bonds (money in) | W4: Bonds Value | X4: Target Value | Y4: Buy/Sell | Z4: Annual Return | AA4: Peak | AB4: Drawdown % | AC4: CAGR % | AD4: Cash price | AE4: Cash (Rs) | AF4: Cash Value | AG4: Target Value | AH4: Buy/Sell | AI4: Annual Return | AJ4: Peak | AK4: Drawdown % | AL4: CAGR % | AM4: Portfolio Value | AN4: Annual Return | AO4: Peak | AP4: Drawdown % | AQ4: CAGR % | AR4: Check: Buy/Sell adds to 0
A5: 1995 Dec | B5: ='Year by year'!C5 | C5: =INDEX(Data!$C$1:$C$500,$B5) | D5: =Calculator!$D$31 | E5: =D5*C5 | F5: =Calculator!$B$5/100*AM5 | G5: =F5-E5 | I5: =E5 | J5: =IF(I5>0,E5/I5-1,0) | L5: =INDEX(Data!$G$1:$G$500,$B5) | M5: =Calculator!$D$32 | N5: =M5*L5 | O5: =Calculator!$B$6/100*AM5 | P5: =O5-N5 | R5: =N5 | S5: =IF(R5>0,N5/R5-1,0) | U5: =INDEX(Monthly!$D$1:$D$500,$B5) | V5: =Calculator!$B$33 | W5: =V5*U5 | X5: =Calculator!$B$7/100*AM5 | Y5: =X5-W5 | AA5: =W5 | AB5: =IF(AA5>0,W5/AA5-1,0) | AD5: 1 | AE5: =Calculator!$B$34 | AF5: =AE5*AD5 | AG5: =Calculator!$B$8/100*AM5 | AH5: =AG5-AF5 | AJ5: =AF5 | AK5: =IF(AJ5>0,AF5/AJ5-1,0) | AM5: =E5+N5+W5+AF5 | AO5: =AM5 | AP5: =AM5/AO5-1 | AR5: =G5+P5+Y5+AH5
A6: 1996 Dec | B6: ='Year by year'!C6 | C6: =INDEX(Data!$C$1:$C$500,$B6) | D6: =Calculator!$D$31 | E6: =D6*C6 | F6: =Calculator!$B$5/100*AM6 | G6: =F6-E6 | H6: =C6/Data!$C$5-1 | I6: =MAX(Calculator!$B$31,E6) | J6: =IF(I6>0,E6/I6-1,0) | K6: =(C6/Data!$C$5)^(12/($B6-5))-1 | L6: =INDEX(Data!$G$1:$G$500,$B6) | M6: =Calculator!$D$32 | N6: =M6*L6 | O6: =Calculator!$B$6/100*AM6 | P6: =O6-N6 | Q6: =L6/Data!$G$5-1 | R6: =MAX(Calculator!$B$32,N6) | S6: =IF(R6>0,N6/R6-1,0) | T6: =(L6/Data!$G$5)^(12/($B6-5))-1 | U6: =INDEX(Monthly!$D$1:$D$500,$B6) | V6: =Calculator!$B$33 | W6: =V6*U6 | X6: =Calculator!$B$7/100*AM6 | Y6: =X6-W6 | Z6: =U6/1-1 | AA6: =MAX(Calculator!$B$33,W6) | AB6: =IF(AA6>0,W6/AA6-1,0) | AC6: =(U6/1)^(12/($B6-5))-1 | AD6: 1 | AE6: =Calculator!$B$34 | AF6: =AE6*AD6 | AG6: =Calculator!$B$8/100*AM6 | AH6: =AG6-AF6 | AI6: =AD6/1-1 | AJ6: =MAX(Calculator!$B$34,AF6) | AK6: =IF(AJ6>0,AF6/AJ6-1,0) | AL6: =(AD6/1)^(12/($B6-5))-1 | AM6: =E6+N6+W6+AF6 | AN6: =AM6/Calculator!$B$4-1 | AO6: =MAX(Calculator!$B$4,AM6) | AP6: =AM6/AO6-1 | AQ6: =(AM6/Calculator!$B$4)^(12/($B6-5))-1 | AR6: =G6+P6+Y6+AH6
A7: 1997 Dec | B7: ='Year by year'!C7 | C7: =INDEX(Data!$C$1:$C$500,$B7) | D7: =Calculator!$D$31 | E7: =D7*C7 | F7: =Calculator!$B$5/100*AM7 | G7: =F7-E7 | H7: =C7/C6-1 | I7: =MAX(I6,E7) | J7: =IF(I7>0,E7/I7-1,0) | K7: =(C7/Data!$C$5)^(12/($B7-5))-1 | L7: =INDEX(Data!$G$1:$G$500,$B7) | M7: =Calculator!$D$32 | N7: =M7*L7 | O7: =Calculator!$B$6/100*AM7 | P7: =O7-N7 | Q7: =L7/L6-1 | R7: =MAX(R6,N7) | S7: =IF(R7>0,N7/R7-1,0) | T7: =(L7/Data!$G$5)^(12/($B7-5))-1 | U7: =INDEX(Monthly!$D$1:$D$500,$B7) | V7: =Calculator!$B$33 | W7: =V7*U7 | X7: =Calculator!$B$7/100*AM7 | Y7: =X7-W7 | Z7: =U7/U6-1 | AA7: =MAX(AA6,W7) | AB7: =IF(AA7>0,W7/AA7-1,0) | AC7: =(U7/1)^(12/($B7-5))-1 | AD7: 1 | AE7: =Calculator!$B$34 | AF7: =AE7*AD7 | AG7: =Calculator!$B$8/100*AM7 | AH7: =AG7-AF7 | AI7: =AD7/AD6-1 | AJ7: =MAX(AJ6,AF7) | AK7: =IF(AJ7>0,AF7/AJ7-1,0) | AL7: =(AD7/1)^(12/($B7-5))-1 | AM7: =E7+N7+W7+AF7 | AN7: =AM7/AM6-1 | AO7: =MAX(AO6,AM7) | AP7: =AM7/AO7-1 | AQ7: =(AM7/Calculator!$B$4)^(12/($B7-5))-1 | AR7: =G7+P7+Y7+AH7
A8: 1998 Dec | B8: ='Year by year'!C8 | C8: =INDEX(Data!$C$1:$C$500,$B8) | D8: =Calculator!$D$31 | E8: =D8*C8 | F8: =Calculator!$B$5/100*AM8 | G8: =F8-E8 | H8: =C8/C7-1 | I8: =MAX(I7,E8) | J8: =IF(I8>0,E8/I8-1,0) | K8: =(C8/Data!$C$5)^(12/($B8-5))-1 | L8: =INDEX(Data!$G$1:$G$500,$B8) | M8: =Calculator!$D$32 | N8: =M8*L8 | O8: =Calculator!$B$6/100*AM8 | P8: =O8-N8 | Q8: =L8/L7-1 | R8: =MAX(R7,N8) | S8: =IF(R8>0,N8/R8-1,0) | T8: =(L8/Data!$G$5)^(12/($B8-5))-1 | U8: =INDEX(Monthly!$D$1:$D$500,$B8) | V8: =Calculator!$B$33 | W8: =V8*U8 | X8: =Calculator!$B$7/100*AM8 | Y8: =X8-W8 | Z8: =U8/U7-1 | AA8: =MAX(AA7,W8) | AB8: =IF(AA8>0,W8/AA8-1,0) | AC8: =(U8/1)^(12/($B8-5))-1 | AD8: 1 | AE8: =Calculator!$B$34 | AF8: =AE8*AD8 | AG8: =Calculator!$B$8/100*AM8 | AH8: =AG8-AF8 | AI8: =AD8/AD7-1 | AJ8: =MAX(AJ7,AF8) | AK8: =IF(AJ8>0,AF8/AJ8-1,0) | AL8: =(AD8/1)^(12/($B8-5))-1 | AM8: =E8+N8+W8+AF8 | AN8: =AM8/AM7-1 | AO8: =MAX(AO7,AM8) | AP8: =AM8/AO8-1 | AQ8: =(AM8/Calculator!$B$4)^(12/($B8-5))-1 | AR8: =G8+P8+Y8+AH8
A9: 1999 Dec | B9: ='Year by year'!C9 | C9: =INDEX(Data!$C$1:$C$500,$B9) | D9: =Calculator!$D$31 | E9: =D9*C9 | F9: =Calculator!$B$5/100*AM9 | G9: =F9-E9 | H9: =C9/C8-1 | I9: =MAX(I8,E9) | J9: =IF(I9>0,E9/I9-1,0) | K9: =(C9/Data!$C$5)^(12/($B9-5))-1 | L9: =INDEX(Data!$G$1:$G$500,$B9) | M9: =Calculator!$D$32 | N9: =M9*L9 | O9: =Calculator!$B$6/100*AM9 | P9: =O9-N9 | Q9: =L9/L8-1 | R9: =MAX(R8,N9) | S9: =IF(R9>0,N9/R9-1,0) | T9: =(L9/Data!$G$5)^(12/($B9-5))-1 | U9: =INDEX(Monthly!$D$1:$D$500,$B9) | V9: =Calculator!$B$33 | W9: =V9*U9 | X9: =Calculator!$B$7/100*AM9 | Y9: =X9-W9 | Z9: =U9/U8-1 | AA9: =MAX(AA8,W9) | AB9: =IF(AA9>0,W9/AA9-1,0) | AC9: =(U9/1)^(12/($B9-5))-1 | AD9: 1 | AE9: =Calculator!$B$34 | AF9: =AE9*AD9 | AG9: =Calculator!$B$8/100*AM9 | AH9: =AG9-AF9 | AI9: =AD9/AD8-1 | AJ9: =MAX(AJ8,AF9) | AK9: =IF(AJ9>0,AF9/AJ9-1,0) | AL9: =(AD9/1)^(12/($B9-5))-1 | AM9: =E9+N9+W9+AF9 | AN9: =AM9/AM8-1 | AO9: =MAX(AO8,AM9) | AP9: =AM9/AO9-1 | AQ9: =(AM9/Calculator!$B$4)^(12/($B9-5))-1 | AR9: =G9+P9+Y9+AH9
A10: 2000 Dec | B10: ='Year by year'!C10 | C10: =INDEX(Data!$C$1:$C$500,$B10) | D10: =Calculator!$D$31 | E10: =D10*C10 | F10: =Calculator!$B$5/100*AM10 | G10: =F10-E10 | H10: =C10/C9-1 | I10: =MAX(I9,E10) | J10: =IF(I10>0,E10/I10-1,0) | K10: =(C10/Data!$C$5)^(12/($B10-5))-1 | L10: =INDEX(Data!$G$1:$G$500,$B10) | M10: =Calculator!$D$32 | N10: =M10*L10 | O10: =Calculator!$B$6/100*AM10 | P10: =O10-N10 | Q10: =L10/L9-1 | R10: =MAX(R9,N10) | S10: =IF(R10>0,N10/R10-1,0) | T10: =(L10/Data!$G$5)^(12/($B10-5))-1 | U10: =INDEX(Monthly!$D$1:$D$500,$B10) | V10: =Calculator!$B$33 | W10: =V10*U10 | X10: =Calculator!$B$7/100*AM10 | Y10: =X10-W10 | Z10: =U10/U9-1 | AA10: =MAX(AA9,W10) | AB10: =IF(AA10>0,W10/AA10-1,0) | AC10: =(U10/1)^(12/($B10-5))-1 | AD10: 1 | AE10: =Calculator!$B$34 | AF10: =AE10*AD10 | AG10: =Calculator!$B$8/100*AM10 | AH10: =AG10-AF10 | AI10: =AD10/AD9-1 | AJ10: =MAX(AJ9,AF10) | AK10: =IF(AJ10>0,AF10/AJ10-1,0) | AL10: =(AD10/1)^(12/($B10-5))-1 | AM10: =E10+N10+W10+AF10 | AN10: =AM10/AM9-1 | AO10: =MAX(AO9,AM10) | AP10: =AM10/AO10-1 | AQ10: =(AM10/Calculator!$B$4)^(12/($B10-5))-1 | AR10: =G10+P10+Y10+AH10
A11: 2001 Dec | B11: ='Year by year'!C11 | C11: =INDEX(Data!$C$1:$C$500,$B11) | D11: =Calculator!$D$31 | E11: =D11*C11 | F11: =Calculator!$B$5/100*AM11 | G11: =F11-E11 | H11: =C11/C10-1 | I11: =MAX(I10,E11) | J11: =IF(I11>0,E11/I11-1,0) | K11: =(C11/Data!$C$5)^(12/($B11-5))-1 | L11: =INDEX(Data!$G$1:$G$500,$B11) | M11: =Calculator!$D$32 | N11: =M11*L11 | O11: =Calculator!$B$6/100*AM11 | P11: =O11-N11 | Q11: =L11/L10-1 | R11: =MAX(R10,N11) | S11: =IF(R11>0,N11/R11-1,0) | T11: =(L11/Data!$G$5)^(12/($B11-5))-1 | U11: =INDEX(Monthly!$D$1:$D$500,$B11) | V11: =Calculator!$B$33 | W11: =V11*U11 | X11: =Calculator!$B$7/100*AM11 | Y11: =X11-W11 | Z11: =U11/U10-1 | AA11: =MAX(AA10,W11) | AB11: =IF(AA11>0,W11/AA11-1,0) | AC11: =(U11/1)^(12/($B11-5))-1 | AD11: 1 | AE11: =Calculator!$B$34 | AF11: =AE11*AD11 | AG11: =Calculator!$B$8/100*AM11 | AH11: =AG11-AF11 | AI11: =AD11/AD10-1 | AJ11: =MAX(AJ10,AF11) | AK11: =IF(AJ11>0,AF11/AJ11-1,0) | AL11: =(AD11/1)^(12/($B11-5))-1 | AM11: =E11+N11+W11+AF11 | AN11: =AM11/AM10-1 | AO11: =MAX(AO10,AM11) | AP11: =AM11/AO11-1 | AQ11: =(AM11/Calculator!$B$4)^(12/($B11-5))-1 | AR11: =G11+P11+Y11+AH11
A12: 2002 Dec | B12: ='Year by year'!C12 | C12: =INDEX(Data!$C$1:$C$500,$B12) | D12: =Calculator!$D$31 | E12: =D12*C12 | F12: =Calculator!$B$5/100*AM12 | G12: =F12-E12 | H12: =C12/C11-1 | I12: =MAX(I11,E12) | J12: =IF(I12>0,E12/I12-1,0) | K12: =(C12/Data!$C$5)^(12/($B12-5))-1 | L12: =INDEX(Data!$G$1:$G$500,$B12) | M12: =Calculator!$D$32 | N12: =M12*L12 | O12: =Calculator!$B$6/100*AM12 | P12: =O12-N12 | Q12: =L12/L11-1 | R12: =MAX(R11,N12) | S12: =IF(R12>0,N12/R12-1,0) | T12: =(L12/Data!$G$5)^(12/($B12-5))-1 | U12: =INDEX(Monthly!$D$1:$D$500,$B12) | V12: =Calculator!$B$33 | W12: =V12*U12 | X12: =Calculator!$B$7/100*AM12 | Y12: =X12-W12 | Z12: =U12/U11-1 | AA12: =MAX(AA11,W12) | AB12: =IF(AA12>0,W12/AA12-1,0) | AC12: =(U12/1)^(12/($B12-5))-1 | AD12: 1 | AE12: =Calculator!$B$34 | AF12: =AE12*AD12 | AG12: =Calculator!$B$8/100*AM12 | AH12: =AG12-AF12 | AI12: =AD12/AD11-1 | AJ12: =MAX(AJ11,AF12) | AK12: =IF(AJ12>0,AF12/AJ12-1,0) | AL12: =(AD12/1)^(12/($B12-5))-1 | AM12: =E12+N12+W12+AF12 | AN12: =AM12/AM11-1 | AO12: =MAX(AO11,AM12) | AP12: =AM12/AO12-1 | AQ12: =(AM12/Calculator!$B$4)^(12/($B12-5))-1 | AR12: =G12+P12+Y12+AH12
A13: 2003 Dec | B13: ='Year by year'!C13 | C13: =INDEX(Data!$C$1:$C$500,$B13) | D13: =Calculator!$D$31 | E13: =D13*C13 | F13: =Calculator!$B$5/100*AM13 | G13: =F13-E13 | H13: =C13/C12-1 | I13: =MAX(I12,E13) | J13: =IF(I13>0,E13/I13-1,0) | K13: =(C13/Data!$C$5)^(12/($B13-5))-1 | L13: =INDEX(Data!$G$1:$G$500,$B13) | M13: =Calculator!$D$32 | N13: =M13*L13 | O13: =Calculator!$B$6/100*AM13 | P13: =O13-N13 | Q13: =L13/L12-1 | R13: =MAX(R12,N13) | S13: =IF(R13>0,N13/R13-1,0) | T13: =(L13/Data!$G$5)^(12/($B13-5))-1 | U13: =INDEX(Monthly!$D$1:$D$500,$B13) | V13: =Calculator!$B$33 | W13: =V13*U13 | X13: =Calculator!$B$7/100*AM13 | Y13: =X13-W13 | Z13: =U13/U12-1 | AA13: =MAX(AA12,W13) | AB13: =IF(AA13>0,W13/AA13-1,0) | AC13: =(U13/1)^(12/($B13-5))-1 | AD13: 1 | AE13: =Calculator!$B$34 | AF13: =AE13*AD13 | AG13: =Calculator!$B$8/100*AM13 | AH13: =AG13-AF13 | AI13: =AD13/AD12-1 | AJ13: =MAX(AJ12,AF13) | AK13: =IF(AJ13>0,AF13/AJ13-1,0) | AL13: =(AD13/1)^(12/($B13-5))-1 | AM13: =E13+N13+W13+AF13 | AN13: =AM13/AM12-1 | AO13: =MAX(AO12,AM13) | AP13: =AM13/AO13-1 | AQ13: =(AM13/Calculator!$B$4)^(12/($B13-5))-1 | AR13: =G13+P13+Y13+AH13
A14: 2004 Dec | B14: ='Year by year'!C14 | C14: =INDEX(Data!$C$1:$C$500,$B14) | D14: =Calculator!$D$31 | E14: =D14*C14 | F14: =Calculator!$B$5/100*AM14 | G14: =F14-E14 | H14: =C14/C13-1 | I14: =MAX(I13,E14) | J14: =IF(I14>0,E14/I14-1,0) | K14: =(C14/Data!$C$5)^(12/($B14-5))-1 | L14: =INDEX(Data!$G$1:$G$500,$B14) | M14: =Calculator!$D$32 | N14: =M14*L14 | O14: =Calculator!$B$6/100*AM14 | P14: =O14-N14 | Q14: =L14/L13-1 | R14: =MAX(R13,N14) | S14: =IF(R14>0,N14/R14-1,0) | T14: =(L14/Data!$G$5)^(12/($B14-5))-1 | U14: =INDEX(Monthly!$D$1:$D$500,$B14) | V14: =Calculator!$B$33 | W14: =V14*U14 | X14: =Calculator!$B$7/100*AM14 | Y14: =X14-W14 | Z14: =U14/U13-1 | AA14: =MAX(AA13,W14) | AB14: =IF(AA14>0,W14/AA14-1,0) | AC14: =(U14/1)^(12/($B14-5))-1 | AD14: 1 | AE14: =Calculator!$B$34 | AF14: =AE14*AD14 | AG14: =Calculator!$B$8/100*AM14 | AH14: =AG14-AF14 | AI14: =AD14/AD13-1 | AJ14: =MAX(AJ13,AF14) | AK14: =IF(AJ14>0,AF14/AJ14-1,0) | AL14: =(AD14/1)^(12/($B14-5))-1 | AM14: =E14+N14+W14+AF14 | AN14: =AM14/AM13-1 | AO14: =MAX(AO13,AM14) | AP14: =AM14/AO14-1 | AQ14: =(AM14/Calculator!$B$4)^(12/($B14-5))-1 | AR14: =G14+P14+Y14+AH14
A15: 2005 Dec | B15: ='Year by year'!C15 | C15: =INDEX(Data!$C$1:$C$500,$B15) | D15: =Calculator!$D$31 | E15: =D15*C15 | F15: =Calculator!$B$5/100*AM15 | G15: =F15-E15 | H15: =C15/C14-1 | I15: =MAX(I14,E15) | J15: =IF(I15>0,E15/I15-1,0) | K15: =(C15/Data!$C$5)^(12/($B15-5))-1 | L15: =INDEX(Data!$G$1:$G$500,$B15) | M15: =Calculator!$D$32 | N15: =M15*L15 | O15: =Calculator!$B$6/100*AM15 | P15: =O15-N15 | Q15: =L15/L14-1 | R15: =MAX(R14,N15) | S15: =IF(R15>0,N15/R15-1,0) | T15: =(L15/Data!$G$5)^(12/($B15-5))-1 | U15: =INDEX(Monthly!$D$1:$D$500,$B15) | V15: =Calculator!$B$33 | W15: =V15*U15 | X15: =Calculator!$B$7/100*AM15 | Y15: =X15-W15 | Z15: =U15/U14-1 | AA15: =MAX(AA14,W15) | AB15: =IF(AA15>0,W15/AA15-1,0) | AC15: =(U15/1)^(12/($B15-5))-1 | AD15: 1 | AE15: =Calculator!$B$34 | AF15: =AE15*AD15 | AG15: =Calculator!$B$8/100*AM15 | AH15: =AG15-AF15 | AI15: =AD15/AD14-1 | AJ15: =MAX(AJ14,AF15) | AK15: =IF(AJ15>0,AF15/AJ15-1,0) | AL15: =(AD15/1)^(12/($B15-5))-1 | AM15: =E15+N15+W15+AF15 | AN15: =AM15/AM14-1 | AO15: =MAX(AO14,AM15) | AP15: =AM15/AO15-1 | AQ15: =(AM15/Calculator!$B$4)^(12/($B15-5))-1 | AR15: =G15+P15+Y15+AH15
A16: 2006 Dec | B16: ='Year by year'!C16 | C16: =INDEX(Data!$C$1:$C$500,$B16) | D16: =Calculator!$D$31 | E16: =D16*C16 | F16: =Calculator!$B$5/100*AM16 | G16: =F16-E16 | H16: =C16/C15-1 | I16: =MAX(I15,E16) | J16: =IF(I16>0,E16/I16-1,0) | K16: =(C16/Data!$C$5)^(12/($B16-5))-1 | L16: =INDEX(Data!$G$1:$G$500,$B16) | M16: =Calculator!$D$32 | N16: =M16*L16 | O16: =Calculator!$B$6/100*AM16 | P16: =O16-N16 | Q16: =L16/L15-1 | R16: =MAX(R15,N16) | S16: =IF(R16>0,N16/R16-1,0) | T16: =(L16/Data!$G$5)^(12/($B16-5))-1 | U16: =INDEX(Monthly!$D$1:$D$500,$B16) | V16: =Calculator!$B$33 | W16: =V16*U16 | X16: =Calculator!$B$7/100*AM16 | Y16: =X16-W16 | Z16: =U16/U15-1 | AA16: =MAX(AA15,W16) | AB16: =IF(AA16>0,W16/AA16-1,0) | AC16: =(U16/1)^(12/($B16-5))-1 | AD16: 1 | AE16: =Calculator!$B$34 | AF16: =AE16*AD16 | AG16: =Calculator!$B$8/100*AM16 | AH16: =AG16-AF16 | AI16: =AD16/AD15-1 | AJ16: =MAX(AJ15,AF16) | AK16: =IF(AJ16>0,AF16/AJ16-1,0) | AL16: =(AD16/1)^(12/($B16-5))-1 | AM16: =E16+N16+W16+AF16 | AN16: =AM16/AM15-1 | AO16: =MAX(AO15,AM16) | AP16: =AM16/AO16-1 | AQ16: =(AM16/Calculator!$B$4)^(12/($B16-5))-1 | AR16: =G16+P16+Y16+AH16
A17: 2007 Dec | B17: ='Year by year'!C17 | C17: =INDEX(Data!$C$1:$C$500,$B17) | D17: =Calculator!$D$31 | E17: =D17*C17 | F17: =Calculator!$B$5/100*AM17 | G17: =F17-E17 | H17: =C17/C16-1 | I17: =MAX(I16,E17) | J17: =IF(I17>0,E17/I17-1,0) | K17: =(C17/Data!$C$5)^(12/($B17-5))-1 | L17: =INDEX(Data!$G$1:$G$500,$B17) | M17: =Calculator!$D$32 | N17: =M17*L17 | O17: =Calculator!$B$6/100*AM17 | P17: =O17-N17 | Q17: =L17/L16-1 | R17: =MAX(R16,N17) | S17: =IF(R17>0,N17/R17-1,0) | T17: =(L17/Data!$G$5)^(12/($B17-5))-1 | U17: =INDEX(Monthly!$D$1:$D$500,$B17) | V17: =Calculator!$B$33 | W17: =V17*U17 | X17: =Calculator!$B$7/100*AM17 | Y17: =X17-W17 | Z17: =U17/U16-1 | AA17: =MAX(AA16,W17) | AB17: =IF(AA17>0,W17/AA17-1,0) | AC17: =(U17/1)^(12/($B17-5))-1 | AD17: 1 | AE17: =Calculator!$B$34 | AF17: =AE17*AD17 | AG17: =Calculator!$B$8/100*AM17 | AH17: =AG17-AF17 | AI17: =AD17/AD16-1 | AJ17: =MAX(AJ16,AF17) | AK17: =IF(AJ17>0,AF17/AJ17-1,0) | AL17: =(AD17/1)^(12/($B17-5))-1 | AM17: =E17+N17+W17+AF17 | AN17: =AM17/AM16-1 | AO17: =MAX(AO16,AM17) | AP17: =AM17/AO17-1 | AQ17: =(AM17/Calculator!$B$4)^(12/($B17-5))-1 | AR17: =G17+P17+Y17+AH17
A18: 2008 Dec | B18: ='Year by year'!C18 | C18: =INDEX(Data!$C$1:$C$500,$B18) | D18: =Calculator!$D$31 | E18: =D18*C18 | F18: =Calculator!$B$5/100*AM18 | G18: =F18-E18 | H18: =C18/C17-1 | I18: =MAX(I17,E18) | J18: =IF(I18>0,E18/I18-1,0) | K18: =(C18/Data!$C$5)^(12/($B18-5))-1 | L18: =INDEX(Data!$G$1:$G$500,$B18) | M18: =Calculator!$D$32 | N18: =M18*L18 | O18: =Calculator!$B$6/100*AM18 | P18: =O18-N18 | Q18: =L18/L17-1 | R18: =MAX(R17,N18) | S18: =IF(R18>0,N18/R18-1,0) | T18: =(L18/Data!$G$5)^(12/($B18-5))-1 | U18: =INDEX(Monthly!$D$1:$D$500,$B18) | V18: =Calculator!$B$33 | W18: =V18*U18 | X18: =Calculator!$B$7/100*AM18 | Y18: =X18-W18 | Z18: =U18/U17-1 | AA18: =MAX(AA17,W18) | AB18: =IF(AA18>0,W18/AA18-1,0) | AC18: =(U18/1)^(12/($B18-5))-1 | AD18: 1 | AE18: =Calculator!$B$34 | AF18: =AE18*AD18 | AG18: =Calculator!$B$8/100*AM18 | AH18: =AG18-AF18 | AI18: =AD18/AD17-1 | AJ18: =MAX(AJ17,AF18) | AK18: =IF(AJ18>0,AF18/AJ18-1,0) | AL18: =(AD18/1)^(12/($B18-5))-1 | AM18: =E18+N18+W18+AF18 | AN18: =AM18/AM17-1 | AO18: =MAX(AO17,AM18) | AP18: =AM18/AO18-1 | AQ18: =(AM18/Calculator!$B$4)^(12/($B18-5))-1 | AR18: =G18+P18+Y18+AH18
... A36: 2026 Sep | B36: ='Year by year'!C36 | C36: =INDEX(Data!$C$1:$C$500,$B36) | D36: =Calculator!$D$31 | E36: =D36*C36 | F36: =Calculator!$B$5/100*AM36 | G36: =F36-E36 | H36: =C36/C35-1 | I36: =MAX(I35,E36) | J36: =IF(I36>0,E36/I36-1,0) | K36: =(C36/Data!$C$5)^(12/($B36-5))-1 | L36: =INDEX(Data!$G$1:$G$500,$B36) | M36: =Calculator!$D$32 | N36: =M36*L36 | O36: =Calculator!$B$6/100*AM36 | P36: =O36-N36 | Q36: =L36/L35-1 | R36: =MAX(R35,N36) | S36: =IF(R36>0,N36/R36-1,0) | T36: =(L36/Data!$G$5)^(12/($B36-5))-1 | U36: =INDEX(Monthly!$D$1:$D$500,$B36) | V36: =Calculator!$B$33 | W36: =V36*U36 | X36: =Calculator!$B$7/100*AM36 | Y36: =X36-W36 | Z36: =U36/U35-1 | AA36: =MAX(AA35,W36) | AB36: =IF(AA36>0,W36/AA36-1,0) | AC36: =(U36/1)^(12/($B36-5))-1 | AD36: 1 | AE36: =Calculator!$B$34 | AF36: =AE36*AD36 | AG36: =Calculator!$B$8/100*AM36 | AH36: =AG36-AF36 | AI36: =AD36/AD35-1 | AJ36: =MAX(AJ35,AF36) | AK36: =IF(AJ36>0,AF36/AJ36-1,0) | AL36: =(AD36/1)^(12/($B36-5))-1 | AM36: =E36+N36+W36+AF36 | AN36: =AM36/AM35-1 | AO36: =MAX(AO35,AM36) | AP36: =AM36/AO36-1 | AQ36: =(AM36/Calculator!$B$4)^(12/($B36-5))-1 | AR36: =G36+P36+Y36+AH36
A38: The first row, 1995 Dec, is what you bought at the Dec 1995 close (closing price, shares / grams, value; nothing has happened yet, so no return). Row in Data = the row of that year's December (2026: the last complete month) in the Data sheet; the tracker needs the Calculator sheet's 'What you bought' section.

Sheet Rebalance year by year
A1: Rebalance year by year (same table as the app's Rebalance page)
A2: Tolerance (points): rebalance in a December only if an asset is more than this far from its target %; 0 = every year | B2: 5
A3: Capital Rs | B3: =Calculator!B4
A4: Asset | B4: Nifty | C4: Gold | D4: Bonds | E4: Cash
A5: Target % | B5: =Calculator!B5 | C5: =Calculator!B6 | D5: =Calculator!B7 | E5: =Calculator!B8
A6: First row = what you bought at the Dec 1995 close. Then every December: the amount in each asset at the December close (shares / grams held x that close), the buy (+) / sell (-) to get back to the target % when the portfolio is rebalanced (Nifty in shares, Gold in grams, at that close), and the amount and shares / grams after. Shares and grams change only in a December when the portfolio is rebalanced; otherwise they stay the same. Bonds and Cash have no units.
A8: Year | B8: Nifty Rs at the Dec close | C8: Nifty shares held | D8: Nifty price (Dec close) | E8: Nifty shares bought(+)/sold(-) at that price | F8: Nifty buy(+)/sell(-) Rs | G8: Nifty Rs after | H8: Nifty shares after | I8: Gold Rs at the Dec close | J8: Gold grams held | K8: Gold Rs per gram (Dec close) | L8: Gold grams bought(+)/sold(-) at that price | M8: Gold buy(+)/sell(-) Rs | N8: Gold Rs after | O8: Gold grams after | P8: Bonds Rs at the Dec close | Q8: Bonds return that year | R8: Bonds buy(+)/sell(-) Rs | S8: Bonds Rs after | T8: Cash Rs at the Dec close | U8: Cash buy(+)/sell(-) Rs | V8: Cash Rs after | W8: Portfolio Rs | X8: Rebalanced? | Y8: Return that year | Z8: Inflation % | AA8: After inflation Rs | AB8: Avg per year so far | AC8: Without rebalancing Rs | AD8: With minus without Rs | AE8: Row in Data (working) | AF8: Max drift, points (working)
A9: 1995 Dec close (buy) | B9: =$B$3*$B$5/100 | C9: =B9/D9 | D9: =INDEX(Data!$C$1:$C$500,$AE9) | E9: =F9/D9 | F9: =IF($X9="Yes",W9*$B$5/100-B9,0) | G9: =B9+F9 | H9: =G9/D9 | I9: =$B$3*$C$5/100 | J9: =I9/K9 | K9: =INDEX(Data!$G$1:$G$500,$AE9) | L9: =M9/K9 | M9: =IF($X9="Yes",W9*$C$5/100-I9,0) | N9: =I9+M9 | O9: =N9/K9 | P9: =$B$3*$D$5/100 | R9: =IF($X9="Yes",W9*$D$5/100-P9,0) | S9: =P9+R9 | T9: =$B$3*$E$5/100 | U9: =IF($X9="Yes",W9*$E$5/100-T9,0) | V9: =T9+U9 | W9: =B9+I9+P9+T9 | X9: Start (buy) | AA9: =W9/INDEX(Monthly!$F$1:$F$500,$AE9) | AC9: =INDEX(Monthly!$K$1:$K$500,$AE9) | AD9: =W9-AC9 | AE9: ='Year by year'!C5 | AF9: =MAX(ABS(B9/W9*100-$B$5),ABS(I9/W9*100-$C$5),ABS(P9/W9*100-$D$5),ABS(T9/W9*100-$E$5))
A10: 1996 Dec | B10: =C10*D10 | C10: =H9 | D10: =INDEX(Data!$C$1:$C$500,$AE10) | E10: =F10/D10 | F10: =IF($X10="Yes",W10*$B$5/100-B10,0) | G10: =B10+F10 | H10: =G10/D10 | I10: =J10*K10 | J10: =O9 | K10: =INDEX(Data!$G$1:$G$500,$AE10) | L10: =M10/K10 | M10: =IF($X10="Yes",W10*$C$5/100-I10,0) | N10: =I10+M10 | O10: =N10/K10 | P10: =S9*INDEX(Monthly!$D$1:$D$500,$AE10)/INDEX(Monthly!$D$1:$D$500,$AE9) | Q10: =INDEX(Monthly!$D$1:$D$500,$AE10)/INDEX(Monthly!$D$1:$D$500,$AE9)-1 | R10: =IF($X10="Yes",W10*$D$5/100-P10,0) | S10: =P10+R10 | T10: =V9 | U10: =IF($X10="Yes",W10*$E$5/100-T10,0) | V10: =T10+U10 | W10: =B10+I10+P10+T10 | X10: =IF(OR($B$2=0,AF10>$B$2),"Yes","No") | Y10: =W10/W9-1 | Z10: =INDEX(Data!$H$1:$H$500,$AE10) | AA10: =W10/INDEX(Monthly!$F$1:$F$500,$AE10) | AB10: =(W10/$B$3)^(12/($AE10-5))-1 | AC10: =INDEX(Monthly!$K$1:$K$500,$AE10) | AD10: =W10-AC10 | AE10: ='Year by year'!C6 | AF10: =MAX(ABS(B10/W10*100-$B$5),ABS(I10/W10*100-$C$5),ABS(P10/W10*100-$D$5),ABS(T10/W10*100-$E$5))
A11: 1997 Dec | B11: =C11*D11 | C11: =H10 | D11: =INDEX(Data!$C$1:$C$500,$AE11) | E11: =F11/D11 | F11: =IF($X11="Yes",W11*$B$5/100-B11,0) | G11: =B11+F11 | H11: =G11/D11 | I11: =J11*K11 | J11: =O10 | K11: =INDEX(Data!$G$1:$G$500,$AE11) | L11: =M11/K11 | M11: =IF($X11="Yes",W11*$C$5/100-I11,0) | N11: =I11+M11 | O11: =N11/K11 | P11: =S10*INDEX(Monthly!$D$1:$D$500,$AE11)/INDEX(Monthly!$D$1:$D$500,$AE10) | Q11: =INDEX(Monthly!$D$1:$D$500,$AE11)/INDEX(Monthly!$D$1:$D$500,$AE10)-1 | R11: =IF($X11="Yes",W11*$D$5/100-P11,0) | S11: =P11+R11 | T11: =V10 | U11: =IF($X11="Yes",W11*$E$5/100-T11,0) | V11: =T11+U11 | W11: =B11+I11+P11+T11 | X11: =IF(OR($B$2=0,AF11>$B$2),"Yes","No") | Y11: =W11/W10-1 | Z11: =INDEX(Data!$H$1:$H$500,$AE11) | AA11: =W11/INDEX(Monthly!$F$1:$F$500,$AE11) | AB11: =(W11/$B$3)^(12/($AE11-5))-1 | AC11: =INDEX(Monthly!$K$1:$K$500,$AE11) | AD11: =W11-AC11 | AE11: ='Year by year'!C7 | AF11: =MAX(ABS(B11/W11*100-$B$5),ABS(I11/W11*100-$C$5),ABS(P11/W11*100-$D$5),ABS(T11/W11*100-$E$5))
A12: 1998 Dec | B12: =C12*D12 | C12: =H11 | D12: =INDEX(Data!$C$1:$C$500,$AE12) | E12: =F12/D12 | F12: =IF($X12="Yes",W12*$B$5/100-B12,0) | G12: =B12+F12 | H12: =G12/D12 | I12: =J12*K12 | J12: =O11 | K12: =INDEX(Data!$G$1:$G$500,$AE12) | L12: =M12/K12 | M12: =IF($X12="Yes",W12*$C$5/100-I12,0) | N12: =I12+M12 | O12: =N12/K12 | P12: =S11*INDEX(Monthly!$D$1:$D$500,$AE12)/INDEX(Monthly!$D$1:$D$500,$AE11) | Q12: =INDEX(Monthly!$D$1:$D$500,$AE12)/INDEX(Monthly!$D$1:$D$500,$AE11)-1 | R12: =IF($X12="Yes",W12*$D$5/100-P12,0) | S12: =P12+R12 | T12: =V11 | U12: =IF($X12="Yes",W12*$E$5/100-T12,0) | V12: =T12+U12 | W12: =B12+I12+P12+T12 | X12: =IF(OR($B$2=0,AF12>$B$2),"Yes","No") | Y12: =W12/W11-1 | Z12: =INDEX(Data!$H$1:$H$500,$AE12) | AA12: =W12/INDEX(Monthly!$F$1:$F$500,$AE12) | AB12: =(W12/$B$3)^(12/($AE12-5))-1 | AC12: =INDEX(Monthly!$K$1:$K$500,$AE12) | AD12: =W12-AC12 | AE12: ='Year by year'!C8 | AF12: =MAX(ABS(B12/W12*100-$B$5),ABS(I12/W12*100-$C$5),ABS(P12/W12*100-$D$5),ABS(T12/W12*100-$E$5))
A13: 1999 Dec | B13: =C13*D13 | C13: =H12 | D13: =INDEX(Data!$C$1:$C$500,$AE13) | E13: =F13/D13 | F13: =IF($X13="Yes",W13*$B$5/100-B13,0) | G13: =B13+F13 | H13: =G13/D13 | I13: =J13*K13 | J13: =O12 | K13: =INDEX(Data!$G$1:$G$500,$AE13) | L13: =M13/K13 | M13: =IF($X13="Yes",W13*$C$5/100-I13,0) | N13: =I13+M13 | O13: =N13/K13 | P13: =S12*INDEX(Monthly!$D$1:$D$500,$AE13)/INDEX(Monthly!$D$1:$D$500,$AE12) | Q13: =INDEX(Monthly!$D$1:$D$500,$AE13)/INDEX(Monthly!$D$1:$D$500,$AE12)-1 | R13: =IF($X13="Yes",W13*$D$5/100-P13,0) | S13: =P13+R13 | T13: =V12 | U13: =IF($X13="Yes",W13*$E$5/100-T13,0) | V13: =T13+U13 | W13: =B13+I13+P13+T13 | X13: =IF(OR($B$2=0,AF13>$B$2),"Yes","No") | Y13: =W13/W12-1 | Z13: =INDEX(Data!$H$1:$H$500,$AE13) | AA13: =W13/INDEX(Monthly!$F$1:$F$500,$AE13) | AB13: =(W13/$B$3)^(12/($AE13-5))-1 | AC13: =INDEX(Monthly!$K$1:$K$500,$AE13) | AD13: =W13-AC13 | AE13: ='Year by year'!C9 | AF13: =MAX(ABS(B13/W13*100-$B$5),ABS(I13/W13*100-$C$5),ABS(P13/W13*100-$D$5),ABS(T13/W13*100-$E$5))
A14: 2000 Dec | B14: =C14*D14 | C14: =H13 | D14: =INDEX(Data!$C$1:$C$500,$AE14) | E14: =F14/D14 | F14: =IF($X14="Yes",W14*$B$5/100-B14,0) | G14: =B14+F14 | H14: =G14/D14 | I14: =J14*K14 | J14: =O13 | K14: =INDEX(Data!$G$1:$G$500,$AE14) | L14: =M14/K14 | M14: =IF($X14="Yes",W14*$C$5/100-I14,0) | N14: =I14+M14 | O14: =N14/K14 | P14: =S13*INDEX(Monthly!$D$1:$D$500,$AE14)/INDEX(Monthly!$D$1:$D$500,$AE13) | Q14: =INDEX(Monthly!$D$1:$D$500,$AE14)/INDEX(Monthly!$D$1:$D$500,$AE13)-1 | R14: =IF($X14="Yes",W14*$D$5/100-P14,0) | S14: =P14+R14 | T14: =V13 | U14: =IF($X14="Yes",W14*$E$5/100-T14,0) | V14: =T14+U14 | W14: =B14+I14+P14+T14 | X14: =IF(OR($B$2=0,AF14>$B$2),"Yes","No") | Y14: =W14/W13-1 | Z14: =INDEX(Data!$H$1:$H$500,$AE14) | AA14: =W14/INDEX(Monthly!$F$1:$F$500,$AE14) | AB14: =(W14/$B$3)^(12/($AE14-5))-1 | AC14: =INDEX(Monthly!$K$1:$K$500,$AE14) | AD14: =W14-AC14 | AE14: ='Year by year'!C10 | AF14: =MAX(ABS(B14/W14*100-$B$5),ABS(I14/W14*100-$C$5),ABS(P14/W14*100-$D$5),ABS(T14/W14*100-$E$5))
A15: 2001 Dec | B15: =C15*D15 | C15: =H14 | D15: =INDEX(Data!$C$1:$C$500,$AE15) | E15: =F15/D15 | F15: =IF($X15="Yes",W15*$B$5/100-B15,0) | G15: =B15+F15 | H15: =G15/D15 | I15: =J15*K15 | J15: =O14 | K15: =INDEX(Data!$G$1:$G$500,$AE15) | L15: =M15/K15 | M15: =IF($X15="Yes",W15*$C$5/100-I15,0) | N15: =I15+M15 | O15: =N15/K15 | P15: =S14*INDEX(Monthly!$D$1:$D$500,$AE15)/INDEX(Monthly!$D$1:$D$500,$AE14) | Q15: =INDEX(Monthly!$D$1:$D$500,$AE15)/INDEX(Monthly!$D$1:$D$500,$AE14)-1 | R15: =IF($X15="Yes",W15*$D$5/100-P15,0) | S15: =P15+R15 | T15: =V14 | U15: =IF($X15="Yes",W15*$E$5/100-T15,0) | V15: =T15+U15 | W15: =B15+I15+P15+T15 | X15: =IF(OR($B$2=0,AF15>$B$2),"Yes","No") | Y15: =W15/W14-1 | Z15: =INDEX(Data!$H$1:$H$500,$AE15) | AA15: =W15/INDEX(Monthly!$F$1:$F$500,$AE15) | AB15: =(W15/$B$3)^(12/($AE15-5))-1 | AC15: =INDEX(Monthly!$K$1:$K$500,$AE15) | AD15: =W15-AC15 | AE15: ='Year by year'!C11 | AF15: =MAX(ABS(B15/W15*100-$B$5),ABS(I15/W15*100-$C$5),ABS(P15/W15*100-$D$5),ABS(T15/W15*100-$E$5))
A16: 2002 Dec | B16: =C16*D16 | C16: =H15 | D16: =INDEX(Data!$C$1:$C$500,$AE16) | E16: =F16/D16 | F16: =IF($X16="Yes",W16*$B$5/100-B16,0) | G16: =B16+F16 | H16: =G16/D16 | I16: =J16*K16 | J16: =O15 | K16: =INDEX(Data!$G$1:$G$500,$AE16) | L16: =M16/K16 | M16: =IF($X16="Yes",W16*$C$5/100-I16,0) | N16: =I16+M16 | O16: =N16/K16 | P16: =S15*INDEX(Monthly!$D$1:$D$500,$AE16)/INDEX(Monthly!$D$1:$D$500,$AE15) | Q16: =INDEX(Monthly!$D$1:$D$500,$AE16)/INDEX(Monthly!$D$1:$D$500,$AE15)-1 | R16: =IF($X16="Yes",W16*$D$5/100-P16,0) | S16: =P16+R16 | T16: =V15 | U16: =IF($X16="Yes",W16*$E$5/100-T16,0) | V16: =T16+U16 | W16: =B16+I16+P16+T16 | X16: =IF(OR($B$2=0,AF16>$B$2),"Yes","No") | Y16: =W16/W15-1 | Z16: =INDEX(Data!$H$1:$H$500,$AE16) | AA16: =W16/INDEX(Monthly!$F$1:$F$500,$AE16) | AB16: =(W16/$B$3)^(12/($AE16-5))-1 | AC16: =INDEX(Monthly!$K$1:$K$500,$AE16) | AD16: =W16-AC16 | AE16: ='Year by year'!C12 | AF16: =MAX(ABS(B16/W16*100-$B$5),ABS(I16/W16*100-$C$5),ABS(P16/W16*100-$D$5),ABS(T16/W16*100-$E$5))
A17: 2003 Dec | B17: =C17*D17 | C17: =H16 | D17: =INDEX(Data!$C$1:$C$500,$AE17) | E17: =F17/D17 | F17: =IF($X17="Yes",W17*$B$5/100-B17,0) | G17: =B17+F17 | H17: =G17/D17 | I17: =J17*K17 | J17: =O16 | K17: =INDEX(Data!$G$1:$G$500,$AE17) | L17: =M17/K17 | M17: =IF($X17="Yes",W17*$C$5/100-I17,0) | N17: =I17+M17 | O17: =N17/K17 | P17: =S16*INDEX(Monthly!$D$1:$D$500,$AE17)/INDEX(Monthly!$D$1:$D$500,$AE16) | Q17: =INDEX(Monthly!$D$1:$D$500,$AE17)/INDEX(Monthly!$D$1:$D$500,$AE16)-1 | R17: =IF($X17="Yes",W17*$D$5/100-P17,0) | S17: =P17+R17 | T17: =V16 | U17: =IF($X17="Yes",W17*$E$5/100-T17,0) | V17: =T17+U17 | W17: =B17+I17+P17+T17 | X17: =IF(OR($B$2=0,AF17>$B$2),"Yes","No") | Y17: =W17/W16-1 | Z17: =INDEX(Data!$H$1:$H$500,$AE17) | AA17: =W17/INDEX(Monthly!$F$1:$F$500,$AE17) | AB17: =(W17/$B$3)^(12/($AE17-5))-1 | AC17: =INDEX(Monthly!$K$1:$K$500,$AE17) | AD17: =W17-AC17 | AE17: ='Year by year'!C13 | AF17: =MAX(ABS(B17/W17*100-$B$5),ABS(I17/W17*100-$C$5),ABS(P17/W17*100-$D$5),ABS(T17/W17*100-$E$5))
A18: 2004 Dec | B18: =C18*D18 | C18: =H17 | D18: =INDEX(Data!$C$1:$C$500,$AE18) | E18: =F18/D18 | F18: =IF($X18="Yes",W18*$B$5/100-B18,0) | G18: =B18+F18 | H18: =G18/D18 | I18: =J18*K18 | J18: =O17 | K18: =INDEX(Data!$G$1:$G$500,$AE18) | L18: =M18/K18 | M18: =IF($X18="Yes",W18*$C$5/100-I18,0) | N18: =I18+M18 | O18: =N18/K18 | P18: =S17*INDEX(Monthly!$D$1:$D$500,$AE18)/INDEX(Monthly!$D$1:$D$500,$AE17) | Q18: =INDEX(Monthly!$D$1:$D$500,$AE18)/INDEX(Monthly!$D$1:$D$500,$AE17)-1 | R18: =IF($X18="Yes",W18*$D$5/100-P18,0) | S18: =P18+R18 | T18: =V17 | U18: =IF($X18="Yes",W18*$E$5/100-T18,0) | V18: =T18+U18 | W18: =B18+I18+P18+T18 | X18: =IF(OR($B$2=0,AF18>$B$2),"Yes","No") | Y18: =W18/W17-1 | Z18: =INDEX(Data!$H$1:$H$500,$AE18) | AA18: =W18/INDEX(Monthly!$F$1:$F$500,$AE18) | AB18: =(W18/$B$3)^(12/($AE18-5))-1 | AC18: =INDEX(Monthly!$K$1:$K$500,$AE18) | AD18: =W18-AC18 | AE18: ='Year by year'!C14 | AF18: =MAX(ABS(B18/W18*100-$B$5),ABS(I18/W18*100-$C$5),ABS(P18/W18*100-$D$5),ABS(T18/W18*100-$E$5))
A19: 2005 Dec | B19: =C19*D19 | C19: =H18 | D19: =INDEX(Data!$C$1:$C$500,$AE19) | E19: =F19/D19 | F19: =IF($X19="Yes",W19*$B$5/100-B19,0) | G19: =B19+F19 | H19: =G19/D19 | I19: =J19*K19 | J19: =O18 | K19: =INDEX(Data!$G$1:$G$500,$AE19) | L19: =M19/K19 | M19: =IF($X19="Yes",W19*$C$5/100-I19,0) | N19: =I19+M19 | O19: =N19/K19 | P19: =S18*INDEX(Monthly!$D$1:$D$500,$AE19)/INDEX(Monthly!$D$1:$D$500,$AE18) | Q19: =INDEX(Monthly!$D$1:$D$500,$AE19)/INDEX(Monthly!$D$1:$D$500,$AE18)-1 | R19: =IF($X19="Yes",W19*$D$5/100-P19,0) | S19: =P19+R19 | T19: =V18 | U19: =IF($X19="Yes",W19*$E$5/100-T19,0) | V19: =T19+U19 | W19: =B19+I19+P19+T19 | X19: =IF(OR($B$2=0,AF19>$B$2),"Yes","No") | Y19: =W19/W18-1 | Z19: =INDEX(Data!$H$1:$H$500,$AE19) | AA19: =W19/INDEX(Monthly!$F$1:$F$500,$AE19) | AB19: =(W19/$B$3)^(12/($AE19-5))-1 | AC19: =INDEX(Monthly!$K$1:$K$500,$AE19) | AD19: =W19-AC19 | AE19: ='Year by year'!C15 | AF19: =MAX(ABS(B19/W19*100-$B$5),ABS(I19/W19*100-$C$5),ABS(P19/W19*100-$D$5),ABS(T19/W19*100-$E$5))
A20: 2006 Dec | B20: =C20*D20 | C20: =H19 | D20: =INDEX(Data!$C$1:$C$500,$AE20) | E20: =F20/D20 | F20: =IF($X20="Yes",W20*$B$5/100-B20,0) | G20: =B20+F20 | H20: =G20/D20 | I20: =J20*K20 | J20: =O19 | K20: =INDEX(Data!$G$1:$G$500,$AE20) | L20: =M20/K20 | M20: =IF($X20="Yes",W20*$C$5/100-I20,0) | N20: =I20+M20 | O20: =N20/K20 | P20: =S19*INDEX(Monthly!$D$1:$D$500,$AE20)/INDEX(Monthly!$D$1:$D$500,$AE19) | Q20: =INDEX(Monthly!$D$1:$D$500,$AE20)/INDEX(Monthly!$D$1:$D$500,$AE19)-1 | R20: =IF($X20="Yes",W20*$D$5/100-P20,0) | S20: =P20+R20 | T20: =V19 | U20: =IF($X20="Yes",W20*$E$5/100-T20,0) | V20: =T20+U20 | W20: =B20+I20+P20+T20 | X20: =IF(OR($B$2=0,AF20>$B$2),"Yes","No") | Y20: =W20/W19-1 | Z20: =INDEX(Data!$H$1:$H$500,$AE20) | AA20: =W20/INDEX(Monthly!$F$1:$F$500,$AE20) | AB20: =(W20/$B$3)^(12/($AE20-5))-1 | AC20: =INDEX(Monthly!$K$1:$K$500,$AE20) | AD20: =W20-AC20 | AE20: ='Year by year'!C16 | AF20: =MAX(ABS(B20/W20*100-$B$5),ABS(I20/W20*100-$C$5),ABS(P20/W20*100-$D$5),ABS(T20/W20*100-$E$5))
A21: 2007 Dec | B21: =C21*D21 | C21: =H20 | D21: =INDEX(Data!$C$1:$C$500,$AE21) | E21: =F21/D21 | F21: =IF($X21="Yes",W21*$B$5/100-B21,0) | G21: =B21+F21 | H21: =G21/D21 | I21: =J21*K21 | J21: =O20 | K21: =INDEX(Data!$G$1:$G$500,$AE21) | L21: =M21/K21 | M21: =IF($X21="Yes",W21*$C$5/100-I21,0) | N21: =I21+M21 | O21: =N21/K21 | P21: =S20*INDEX(Monthly!$D$1:$D$500,$AE21)/INDEX(Monthly!$D$1:$D$500,$AE20) | Q21: =INDEX(Monthly!$D$1:$D$500,$AE21)/INDEX(Monthly!$D$1:$D$500,$AE20)-1 | R21: =IF($X21="Yes",W21*$D$5/100-P21,0) | S21: =P21+R21 | T21: =V20 | U21: =IF($X21="Yes",W21*$E$5/100-T21,0) | V21: =T21+U21 | W21: =B21+I21+P21+T21 | X21: =IF(OR($B$2=0,AF21>$B$2),"Yes","No") | Y21: =W21/W20-1 | Z21: =INDEX(Data!$H$1:$H$500,$AE21) | AA21: =W21/INDEX(Monthly!$F$1:$F$500,$AE21) | AB21: =(W21/$B$3)^(12/($AE21-5))-1 | AC21: =INDEX(Monthly!$K$1:$K$500,$AE21) | AD21: =W21-AC21 | AE21: ='Year by year'!C17 | AF21: =MAX(ABS(B21/W21*100-$B$5),ABS(I21/W21*100-$C$5),ABS(P21/W21*100-$D$5),ABS(T21/W21*100-$E$5))
... A39: 2025 Dec | B39: =C39*D39 | C39: =H38 | D39: =INDEX(Data!$C$1:$C$500,$AE39) | E39: =F39/D39 | F39: =IF($X39="Yes",W39*$B$5/100-B39,0) | G39: =B39+F39 | H39: =G39/D39 | I39: =J39*K39 | J39: =O38 | K39: =INDEX(Data!$G$1:$G$500,$AE39) | L39: =M39/K39 | M39: =IF($X39="Yes",W39*$C$5/100-I39,0) | N39: =I39+M39 | O39: =N39/K39 | P39: =S38*INDEX(Monthly!$D$1:$D$500,$AE39)/INDEX(Monthly!$D$1:$D$500,$AE38) | Q39: =INDEX(Monthly!$D$1:$D$500,$AE39)/INDEX(Monthly!$D$1:$D$500,$AE38)-1 | R39: =IF($X39="Yes",W39*$D$5/100-P39,0) | S39: =P39+R39 | T39: =V38 | U39: =IF($X39="Yes",W39*$E$5/100-T39,0) | V39: =T39+U39 | W39: =B39+I39+P39+T39 | X39: =IF(OR($B$2=0,AF39>$B$2),"Yes","No") | Y39: =W39/W38-1 | Z39: =INDEX(Data!$H$1:$H$500,$AE39) | AA39: =W39/INDEX(Monthly!$F$1:$F$500,$AE39) | AB39: =(W39/$B$3)^(12/($AE39-5))-1 | AC39: =INDEX(Monthly!$K$1:$K$500,$AE39) | AD39: =W39-AC39 | AE39: ='Year by year'!C35 | AF39: =MAX(ABS(B39/W39*100-$B$5),ABS(I39/W39*100-$C$5),ABS(P39/W39*100-$D$5),ABS(T39/W39*100-$E$5))
A40: 2026 Sep | B40: =C40*D40 | C40: =H39 | D40: =INDEX(Data!$C$1:$C$500,$AE40) | E40: =F40/D40 | F40: =IF($X40="Yes",W40*$B$5/100-B40,0) | G40: =B40+F40 | H40: =G40/D40 | I40: =J40*K40 | J40: =O39 | K40: =INDEX(Data!$G$1:$G$500,$AE40) | L40: =M40/K40 | M40: =IF($X40="Yes",W40*$C$5/100-I40,0) | N40: =I40+M40 | O40: =N40/K40 | P40: =S39*INDEX(Monthly!$D$1:$D$500,$AE40)/INDEX(Monthly!$D$1:$D$500,$AE39) | Q40: =INDEX(Monthly!$D$1:$D$500,$AE40)/INDEX(Monthly!$D$1:$D$500,$AE39)-1 | R40: =IF($X40="Yes",W40*$D$5/100-P40,0) | S40: =P40+R40 | T40: =V39 | U40: =IF($X40="Yes",W40*$E$5/100-T40,0) | V40: =T40+U40 | W40: =B40+I40+P40+T40 | X40: no December yet | Y40: =W40/W39-1 | Z40: =INDEX(Data!$H$1:$H$500,$AE40) | AA40: =W40/INDEX(Monthly!$F$1:$F$500,$AE40) | AB40: =(W40/$B$3)^(12/($AE40-5))-1 | AC40: =INDEX(Monthly!$K$1:$K$500,$AE40) | AD40: =W40-AC40 | AE40: ='Year by year'!C36 | AF40: =MAX(ABS(B40/W40*100-$B$5),ABS(I40/W40*100-$C$5),ABS(P40/W40*100-$D$5),ABS(T40/W40*100-$E$5))
A42: Final value with rebalancing Rs | B42: =W40
A43: Final value without rebalancing (buy and hold) Rs | B43: =AC40
A44: Difference Rs | B44: =W40-AC40
A45: Years rebalanced | B45: =COUNTIF(X9:X40,"Yes")
A46: Growth per year with rebalancing | B46: =(W40/$B$3)^(12/(AE40-5))-1
A47: Growth per year without rebalancing | B47: =(AC40/$B$3)^(12/(AE40-5))-1
A48: Value after inflation with rebalancing Rs | B48: =AA40
A49: Nifty shares held at the end (start: the 1995 Dec row) | B49: =H40
A50: Nifty shares bought in all rebalances | B50: =SUMIF(E9:E40,">0")
A51: Nifty shares sold in all rebalances | B51: =-SUMIF(E9:E40,"<0")
A52: Gold grams held at the end (start: the 1995 Dec row) | B52: =O40
A53: Gold grams bought in all rebalances | B53: =SUMIF(L9:L40,">0")
A54: Gold grams sold in all rebalances | B54: =-SUMIF(L9:L40,"<0")
A56: The last row ends at the last complete month (no December review yet). Change B2 to 0 to rebalance every December.

Sheet Year-end comparison
A1: Year-end comparison: buy and hold vs with rebalancing (tolerance from 'Rebalance year by year'!B2)
A2: Tolerance (points) | B2: ='Rebalance year by year'!B2
A4: Year | B4: Buy & hold Rs | C4: With rebalance Rs | D4: Difference Rs | E4: Action
A5: ='Rebalance year by year'!A10 | B5: ='Rebalance year by year'!AC10 | C5: ='Rebalance year by year'!W10 | D5: ='Rebalance year by year'!W10-'Rebalance year by year'!AC10 | E5: =IF('Rebalance year by year'!X10="Yes","Rebalanced",IF('Rebalance year by year'!X10="No","Within band",'Rebalance year by year'!X10))
A6: ='Rebalance year by year'!A11 | B6: ='Rebalance year by year'!AC11 | C6: ='Rebalance year by year'!W11 | D6: ='Rebalance year by year'!W11-'Rebalance year by year'!AC11 | E6: =IF('Rebalance year by year'!X11="Yes","Rebalanced",IF('Rebalance year by year'!X11="No","Within band",'Rebalance year by year'!X11))
A7: ='Rebalance year by year'!A12 | B7: ='Rebalance year by year'!AC12 | C7: ='Rebalance year by year'!W12 | D7: ='Rebalance year by year'!W12-'Rebalance year by year'!AC12 | E7: =IF('Rebalance year by year'!X12="Yes","Rebalanced",IF('Rebalance year by year'!X12="No","Within band",'Rebalance year by year'!X12))
A8: ='Rebalance year by year'!A13 | B8: ='Rebalance year by year'!AC13 | C8: ='Rebalance year by year'!W13 | D8: ='Rebalance year by year'!W13-'Rebalance year by year'!AC13 | E8: =IF('Rebalance year by year'!X13="Yes","Rebalanced",IF('Rebalance year by year'!X13="No","Within band",'Rebalance year by year'!X13))
A9: ='Rebalance year by year'!A14 | B9: ='Rebalance year by year'!AC14 | C9: ='Rebalance year by year'!W14 | D9: ='Rebalance year by year'!W14-'Rebalance year by year'!AC14 | E9: =IF('Rebalance year by year'!X14="Yes","Rebalanced",IF('Rebalance year by year'!X14="No","Within band",'Rebalance year by year'!X14))
A10: ='Rebalance year by year'!A15 | B10: ='Rebalance year by year'!AC15 | C10: ='Rebalance year by year'!W15 | D10: ='Rebalance year by year'!W15-'Rebalance year by year'!AC15 | E10: =IF('Rebalance year by year'!X15="Yes","Rebalanced",IF('Rebalance year by year'!X15="No","Within band",'Rebalance year by year'!X15))
A11: ='Rebalance year by year'!A16 | B11: ='Rebalance year by year'!AC16 | C11: ='Rebalance year by year'!W16 | D11: ='Rebalance year by year'!W16-'Rebalance year by year'!AC16 | E11: =IF('Rebalance year by year'!X16="Yes","Rebalanced",IF('Rebalance year by year'!X16="No","Within band",'Rebalance year by year'!X16))
A12: ='Rebalance year by year'!A17 | B12: ='Rebalance year by year'!AC17 | C12: ='Rebalance year by year'!W17 | D12: ='Rebalance year by year'!W17-'Rebalance year by year'!AC17 | E12: =IF('Rebalance year by year'!X17="Yes","Rebalanced",IF('Rebalance year by year'!X17="No","Within band",'Rebalance year by year'!X17))
A13: ='Rebalance year by year'!A18 | B13: ='Rebalance year by year'!AC18 | C13: ='Rebalance year by year'!W18 | D13: ='Rebalance year by year'!W18-'Rebalance year by year'!AC18 | E13: =IF('Rebalance year by year'!X18="Yes","Rebalanced",IF('Rebalance year by year'!X18="No","Within band",'Rebalance year by year'!X18))
A14: ='Rebalance year by year'!A19 | B14: ='Rebalance year by year'!AC19 | C14: ='Rebalance year by year'!W19 | D14: ='Rebalance year by year'!W19-'Rebalance year by year'!AC19 | E14: =IF('Rebalance year by year'!X19="Yes","Rebalanced",IF('Rebalance year by year'!X19="No","Within band",'Rebalance year by year'!X19))
A15: ='Rebalance year by year'!A20 | B15: ='Rebalance year by year'!AC20 | C15: ='Rebalance year by year'!W20 | D15: ='Rebalance year by year'!W20-'Rebalance year by year'!AC20 | E15: =IF('Rebalance year by year'!X20="Yes","Rebalanced",IF('Rebalance year by year'!X20="No","Within band",'Rebalance year by year'!X20))
A16: ='Rebalance year by year'!A21 | B16: ='Rebalance year by year'!AC21 | C16: ='Rebalance year by year'!W21 | D16: ='Rebalance year by year'!W21-'Rebalance year by year'!AC21 | E16: =IF('Rebalance year by year'!X21="Yes","Rebalanced",IF('Rebalance year by year'!X21="No","Within band",'Rebalance year by year'!X21))
... A35: ='Rebalance year by year'!A40 | B35: ='Rebalance year by year'!AC40 | C35: ='Rebalance year by year'!W40 | D35: ='Rebalance year by year'!W40-'Rebalance year by year'!AC40 | E35: =IF('Rebalance year by year'!X40="Yes","Rebalanced",IF('Rebalance year by year'!X40="No","Within band",'Rebalance year by year'!X40))

Sheet Bonds calculation
A1: Bonds calculation, year by year
A2: Until 2011 a year's Bonds return is the SBI year-end FD rate (its first value, 9.00%, is applied to 1996-98 because the SBI series starts in 1999). 2012-2014 use the 2011 rate (no data). From 2015 it is the move of the NIFTY Composite G-sec Index: this period's close / last December's close - 1 (the index starts on 2015-10-13, so 2015 runs from that first close; 2026 runs from the 2025 December close to the last complete month). The whole year's return is added once, in December (2026: in the last complete month); the other months get 0%. Bonds x = previous Bonds x x (1 + return).
A3: Capital Rs | B3: =Calculator!B4 | D3: Bonds % | E3: =Calculator!B7
A5: Year | B5: Source | C5: FD rate % (until 2014) | D5: G-sec close (end of period) | E5: G-sec close (start) | F5: Months in period | G5: Return % of the period | H5: How the return is worked out | I5: Bonds x | J5: 100% in Bonds: value Rs | K5: Your Bonds amount: value Rs | L5: Added in month (1-12)
A6: 1996 | B6: SBI first value (1999) applied | C6: =C9 | F6: 12 | G6: =C6 | H6: ="FD rate of the year = "&TEXT(C6,"0.00")&"%" | I6: =1*(1+G6/100) | J6: =$B$3*I6 | K6: =$B$3*$E$3/100*I6 | L6: =F6
A7: 1997 | B7: SBI first value (1999) applied | C7: =C9 | F7: 12 | G7: =C7 | H7: ="FD rate of the year = "&TEXT(C7,"0.00")&"%" | I7: =I6*(1+G7/100) | J7: =$B$3*I7 | K7: =$B$3*$E$3/100*I7 | L7: =F7
A8: 1998 | B8: SBI first value (1999) applied | C8: =C9 | F8: 12 | G8: =C8 | H8: ="FD rate of the year = "&TEXT(C8,"0.00")&"%" | I8: =I7*(1+G8/100) | J8: =$B$3*I8 | K8: =$B$3*$E$3/100*I8 | L8: =F8
A9: 1999 | B9: SBI year-end (API) | C9: 9 | F9: 12 | G9: =C9 | H9: ="FD rate of the year = "&TEXT(C9,"0.00")&"%" | I9: =I8*(1+G9/100) | J9: =$B$3*I9 | K9: =$B$3*$E$3/100*I9 | L9: =F9
A10: 2000 | B10: SBI year-end (API) | C10: 8.5 | F10: 12 | G10: =C10 | H10: ="FD rate of the year = "&TEXT(C10,"0.00")&"%" | I10: =I9*(1+G10/100) | J10: =$B$3*I10 | K10: =$B$3*$E$3/100*I10 | L10: =F10
A11: 2001 | B11: SBI year-end (API) | C11: 7.75 | F11: 12 | G11: =C11 | H11: ="FD rate of the year = "&TEXT(C11,"0.00")&"%" | I11: =I10*(1+G11/100) | J11: =$B$3*I11 | K11: =$B$3*$E$3/100*I11 | L11: =F11
A12: 2002 | B12: SBI year-end (API) | C12: 6.5 | F12: 12 | G12: =C12 | H12: ="FD rate of the year = "&TEXT(C12,"0.00")&"%" | I12: =I11*(1+G12/100) | J12: =$B$3*I12 | K12: =$B$3*$E$3/100*I12 | L12: =F12
